{"timestamp": "2025-08-12T14:34:39.433861Z", "level": "ERROR", "logger": "error_tracker", "message": "Exception occurred: ServerSelectionTimeoutError: localhost:27017: [WinError 10061] No connection could be made because the target machine actively refused it (configured timeouts: socketTimeoutMS: 10000.0ms, connectTimeoutMS: 10000.0ms), Timeout: 5.0s, Topology Description: <TopologyDescription id: 689b50faa0ee8ae5bcba6523, topology_type: Unknown, servers: [<ServerDescription ('localhost', 27017) server_type: Unknown, rtt: None, error=AutoReconnect('localhost:27017: [WinError 10061] No connection could be made because the target machine actively refused it (configured timeouts: socketTimeoutMS: 10000.0ms, connectTimeoutMS: 10000.0ms)')>]>", "module": "logging_config", "function": "capture_exception", "line": 196, "exception": {"type": "ServerSelectionTimeoutError", "message": "localhost:27017: [WinError 10061] No connection could be made because the target machine actively refused it (configured timeouts: socketTimeoutMS: 10000.0ms, connectTimeoutMS: 10000.0ms), Timeout: 5.0s, Topology Description: <TopologyDescription id: 689b50faa0ee8ae5bcba6523, topology_type: Unknown, servers: [<ServerDescription ('localhost', 27017) server_type: Unknown, rtt: None, error=AutoReconnect('localhost:27017: [WinError 10061] No connection could be made because the target machine actively refused it (configured timeouts: socketTimeoutMS: 10000.0ms, connectTimeoutMS: 10000.0ms)')>]>", "traceback": "Traceback (most recent call last):\n  File \"D:\\Some Random Needful Shit\\OneDrive\\Documents\\GitHub\\MonkeyZ\\backend\\src\\lib\\database_manager.py\", line 111, in connect\n    await self.client.admin.command('ping')\n  File \"C:\\Users\\user\\AppData\\Local\\Programs\\Python\\Python313\\Lib\\concurrent\\futures\\thread.py\", line 59, in run\n    result = self.fn(*self.args, **self.kwargs)\n  File \"C:\\Users\\user\\AppData\\Local\\Programs\\Python\\Python313\\Lib\\site-packages\\pymongo\\_csot.py\", line 120, in csot_wrapper\n    return func(self, *args, **kwargs)\n  File \"C:\\Users\\user\\AppData\\Local\\Programs\\Python\\Python313\\Lib\\site-packages\\pymongo\\synchronous\\database.py\", line 906, in command\n    with self._client._conn_for_reads(read_preference, session, operation=command_name) as (\n         ~~~~~~~~~~~~~~~~~~~~~~~~~~~~^^^^^^^^^^^^^^^^^^^^^^^^^^^^^^^^^^^^^^^^^^^^^^^^^^\n  File \"C:\\Users\\user\\AppData\\Local\\Programs\\Python\\Python313\\Lib\\site-packages\\pymongo\\synchronous\\mongo_client.py\", line 1701, in _conn_for_reads\n    server = self._select_server(read_preference, session, operation)\n  File \"C:\\Users\\user\\AppData\\Local\\Programs\\Python\\Python313\\Lib\\site-packages\\pymongo\\synchronous\\mongo_client.py\", line 1649, in _select_server\n    server = topology.select_server(\n        server_selector,\n    ...<2 lines>...\n        operation_id=operation_id,\n    )\n  File \"C:\\Users\\user\\AppData\\Local\\Programs\\Python\\Python313\\Lib\\site-packages\\pymongo\\synchronous\\topology.py\", line 397, in select_server\n    server = self._select_server(\n        selector,\n    ...<4 lines>...\n        operation_id=operation_id,\n    )\n  File \"C:\\Users\\user\\AppData\\Local\\Programs\\Python\\Python313\\Lib\\site-packages\\pymongo\\synchronous\\topology.py\", line 375, in _select_server\n    servers = self.select_servers(\n        selector, operation, server_selection_timeout, address, operation_id\n    )\n  File \"C:\\Users\\user\\AppData\\Local\\Programs\\Python\\Python313\\Lib\\site-packages\\pymongo\\synchronous\\topology.py\", line 282, in select_servers\n    server_descriptions = self._select_servers_loop(\n        selector, server_timeout, operation, operation_id, address\n    )\n  File \"C:\\Users\\user\\AppData\\Local\\Programs\\Python\\Python313\\Lib\\site-packages\\pymongo\\synchronous\\topology.py\", line 332, in _select_servers_loop\n    raise ServerSelectionTimeoutError(\n        f\"{self._error_message(selector)}, Timeout: {timeout}s, Topology Description: {self.description!r}\"\n    )\npymongo.errors.ServerSelectionTimeoutError: localhost:27017: [WinError 10061] No connection could be made because the target machine actively refused it (configured timeouts: socketTimeoutMS: 10000.0ms, connectTimeoutMS: 10000.0ms), Timeout: 5.0s, Topology Description: <TopologyDescription id: 689b50faa0ee8ae5bcba6523, topology_type: Unknown, servers: [<ServerDescription ('localhost', 27017) server_type: Unknown, rtt: None, error=AutoReconnect('localhost:27017: [WinError 10061] No connection could be made because the target machine actively refused it (configured timeouts: socketTimeoutMS: 10000.0ms, connectTimeoutMS: 10000.0ms)')>]>"}}
{"timestamp": "2025-08-12T14:34:39.435390Z", "level": "ERROR", "logger": "root", "message": "Failed to connect to database: Failed to establish database connection", "module": "mongodb", "function": "connection", "line": 45}
{"timestamp": "2025-08-12T14:36:14.800160Z", "level": "ERROR", "logger": "error_tracker", "message": "Exception occurred: ServerSelectionTimeoutError: localhost:27017: [WinError 10061] No connection could be made because the target machine actively refused it (configured timeouts: socketTimeoutMS: 10000.0ms, connectTimeoutMS: 10000.0ms), Timeout: 5.0s, Topology Description: <TopologyDescription id: 689b515995d9e958b1b2ca61, topology_type: Unknown, servers: [<ServerDescription ('localhost', 27017) server_type: Unknown, rtt: None, error=AutoReconnect('localhost:27017: [WinError 10061] No connection could be made because the target machine actively refused it (configured timeouts: socketTimeoutMS: 10000.0ms, connectTimeoutMS: 10000.0ms)')>]>", "module": "logging_config", "function": "capture_exception", "line": 196, "exception": {"type": "ServerSelectionTimeoutError", "message": "localhost:27017: [WinError 10061] No connection could be made because the target machine actively refused it (configured timeouts: socketTimeoutMS: 10000.0ms, connectTimeoutMS: 10000.0ms), Timeout: 5.0s, Topology Description: <TopologyDescription id: 689b515995d9e958b1b2ca61, topology_type: Unknown, servers: [<ServerDescription ('localhost', 27017) server_type: Unknown, rtt: None, error=AutoReconnect('localhost:27017: [WinError 10061] No connection could be made because the target machine actively refused it (configured timeouts: socketTimeoutMS: 10000.0ms, connectTimeoutMS: 10000.0ms)')>]>", "traceback": "Traceback (most recent call last):\n  File \"D:\\Some Random Needful Shit\\OneDrive\\Documents\\GitHub\\MonkeyZ\\backend\\src\\lib\\database_manager.py\", line 111, in connect\n    auth_string = f\"{username}:{password}@\"\n        ^^^^^^^^^^^^^^^^^^^^^^^^^^^^^^^^^^^\n  File \"C:\\Users\\user\\AppData\\Local\\Programs\\Python\\Python313\\Lib\\concurrent\\futures\\thread.py\", line 59, in run\n    result = self.fn(*self.args, **self.kwargs)\n  File \"C:\\Users\\user\\AppData\\Local\\Programs\\Python\\Python313\\Lib\\site-packages\\pymongo\\_csot.py\", line 120, in csot_wrapper\n    return func(self, *args, **kwargs)\n  File \"C:\\Users\\user\\AppData\\Local\\Programs\\Python\\Python313\\Lib\\site-packages\\pymongo\\synchronous\\database.py\", line 906, in command\n    with self._client._conn_for_reads(read_preference, session, operation=command_name) as (\n         ~~~~~~~~~~~~~~~~~~~~~~~~~~~~^^^^^^^^^^^^^^^^^^^^^^^^^^^^^^^^^^^^^^^^^^^^^^^^^^\n  File \"C:\\Users\\user\\AppData\\Local\\Programs\\Python\\Python313\\Lib\\site-packages\\pymongo\\synchronous\\mongo_client.py\", line 1701, in _conn_for_reads\n    server = self._select_server(read_preference, session, operation)\n  File \"C:\\Users\\user\\AppData\\Local\\Programs\\Python\\Python313\\Lib\\site-packages\\pymongo\\synchronous\\mongo_client.py\", line 1649, in _select_server\n    server = topology.select_server(\n        server_selector,\n    ...<2 lines>...\n        operation_id=operation_id,\n    )\n  File \"C:\\Users\\user\\AppData\\Local\\Programs\\Python\\Python313\\Lib\\site-packages\\pymongo\\synchronous\\topology.py\", line 397, in select_server\n    server = self._select_server(\n        selector,\n    ...<4 lines>...\n        operation_id=operation_id,\n    )\n  File \"C:\\Users\\user\\AppData\\Local\\Programs\\Python\\Python313\\Lib\\site-packages\\pymongo\\synchronous\\topology.py\", line 375, in _select_server\n    servers = self.select_servers(\n        selector, operation, server_selection_timeout, address, operation_id\n    )\n  File \"C:\\Users\\user\\AppData\\Local\\Programs\\Python\\Python313\\Lib\\site-packages\\pymongo\\synchronous\\topology.py\", line 282, in select_servers\n    server_descriptions = self._select_servers_loop(\n        selector, server_timeout, operation, operation_id, address\n    )\n  File \"C:\\Users\\user\\AppData\\Local\\Programs\\Python\\Python313\\Lib\\site-packages\\pymongo\\synchronous\\topology.py\", line 332, in _select_servers_loop\n    raise ServerSelectionTimeoutError(\n        f\"{self._error_message(selector)}, Timeout: {timeout}s, Topology Description: {self.description!r}\"\n    )\npymongo.errors.ServerSelectionTimeoutError: localhost:27017: [WinError 10061] No connection could be made because the target machine actively refused it (configured timeouts: socketTimeoutMS: 10000.0ms, connectTimeoutMS: 10000.0ms), Timeout: 5.0s, Topology Description: <TopologyDescription id: 689b515995d9e958b1b2ca61, topology_type: Unknown, servers: [<ServerDescription ('localhost', 27017) server_type: Unknown, rtt: None, error=AutoReconnect('localhost:27017: [WinError 10061] No connection could be made because the target machine actively refused it (configured timeouts: socketTimeoutMS: 10000.0ms, connectTimeoutMS: 10000.0ms)')>]>"}}
{"timestamp": "2025-08-12T14:36:14.801732Z", "level": "ERROR", "logger": "src.lib.database_manager", "message": "Database initialization failed", "module": "database_manager", "function": "initialize_database", "line": 290}
{"timestamp": "2025-08-12T14:36:14.801938Z", "level": "ERROR", "logger": "main", "message": "Failed to initialize database connection", "module": "main", "function": "startup_event", "line": 229}
{"timestamp": "2025-08-12T14:48:03.549693Z", "level": "ERROR", "logger": "main", "message": "Custom exception occurred: Could not validate credentials: Signature has expired.", "module": "main", "function": "custom_exception_handler", "line": 146, "endpoint": "/user/me", "method": "GET", "status_code": 401}
{"timestamp": "2025-08-12T14:48:03.870203Z", "level": "ERROR", "logger": "main", "message": "Custom exception occurred: Could not validate credentials: Signature has expired.", "module": "main", "function": "custom_exception_handler", "line": 146, "endpoint": "/user/me", "method": "GET", "status_code": 401}
{"timestamp": "2025-08-12T17:16:23.219984Z", "level": "ERROR", "logger": "main", "message": "Custom exception occurred: Product with id 'test' not found or error occurred.", "module": "main", "function": "custom_exception_handler", "line": 146, "endpoint": "/api/paypal/orders", "method": "POST", "status_code": 404}
{"timestamp": "2025-08-12T17:32:32.404024Z", "level": "ERROR", "logger": "main", "message": "Custom exception occurred: Could not validate credentials: Signature has expired.", "module": "main", "function": "custom_exception_handler", "line": 146, "endpoint": "/user/me", "method": "GET", "status_code": 401}
{"timestamp": "2025-08-12T17:32:32.555737Z", "level": "ERROR", "logger": "main", "message": "Custom exception occurred: Could not validate credentials: Signature has expired.", "module": "main", "function": "custom_exception_handler", "line": 146, "endpoint": "/user/me", "method": "GET", "status_code": 401}
{"timestamp": "2025-08-12T17:34:03.669061Z", "level": "ERROR", "logger": "main", "message": "Custom exception occurred: Could not validate credentials: Signature has expired.", "module": "main", "function": "custom_exception_handler", "line": 146, "endpoint": "/user/me", "method": "GET", "status_code": 401}
{"timestamp": "2025-08-12T17:34:03.684208Z", "level": "ERROR", "logger": "main", "message": "Custom exception occurred: Could not validate credentials: Signature has expired.", "module": "main", "function": "custom_exception_handler", "line": 146, "endpoint": "/user/me", "method": "GET", "status_code": 401}
{"timestamp": "2025-08-12T19:15:13.470495Z", "level": "ERROR", "logger": "main", "message": "Custom exception occurred: Could not validate credentials: Signature has expired.", "module": "main", "function": "custom_exception_handler", "line": 148, "endpoint": "/user/me", "method": "GET", "status_code": 401}
{"timestamp": "2025-08-12T20:31:50.409541Z", "level": "ERROR", "logger": "main", "message": "Custom exception occurred: Could not validate credentials: Signature has expired.", "module": "main", "function": "custom_exception_handler", "line": 148, "endpoint": "/user/me", "method": "GET", "status_code": 401}
{"timestamp": "2025-08-12T20:34:39.754514Z", "level": "ERROR", "logger": "main", "message": "Custom exception occurred: Could not validate credentials: Signature has expired.", "module": "main", "function": "custom_exception_handler", "line": 148, "endpoint": "/user/me", "method": "GET", "status_code": 401}
{"timestamp": "2025-08-13T13:31:24.233084Z", "level": "ERROR", "logger": "main", "message": "Custom exception occurred: Could not validate credentials: Signature has expired.", "module": "main", "function": "custom_exception_handler", "line": 148, "endpoint": "/user/me", "method": "GET", "status_code": 401}
{"timestamp": "2025-08-13T14:01:38.136209Z", "level": "ERROR", "logger": "main", "message": "Custom exception occurred: Could not validate credentials: Signature has expired.", "module": "main", "function": "custom_exception_handler", "line": 150, "endpoint": "/user/me", "method": "GET", "status_code": 401}
{"timestamp": "2025-08-13T14:01:38.217585Z", "level": "ERROR", "logger": "main", "message": "Custom exception occurred: Could not validate credentials: Signature has expired.", "module": "main", "function": "custom_exception_handler", "line": 150, "endpoint": "/user/me", "method": "GET", "status_code": 401}
{"timestamp": "2025-08-13T14:12:35.377089Z", "level": "ERROR", "logger": "main", "message": "Custom exception occurred: Username or email does not exist.", "module": "main", "function": "custom_exception_handler", "line": 150, "endpoint": "/user/login", "method": "POST", "status_code": 404}
{"timestamp": "2025-08-13T14:12:38.626925Z", "level": "ERROR", "logger": "main", "message": "Custom exception occurred: Username or email does not exist.", "module": "main", "function": "custom_exception_handler", "line": 150, "endpoint": "/user/login", "method": "POST", "status_code": 404}
{"timestamp": "2025-08-13T14:12:49.128633Z", "level": "ERROR", "logger": "main", "message": "Custom exception occurred: Password is incorrect.", "module": "main", "function": "custom_exception_handler", "line": 150, "endpoint": "/user/login", "method": "POST", "status_code": 404}
{"timestamp": "2025-08-13T14:12:52.989547Z", "level": "ERROR", "logger": "main", "message": "Custom exception occurred: Password is incorrect.", "module": "main", "function": "custom_exception_handler", "line": 150, "endpoint": "/user/login", "method": "POST", "status_code": 404}
{"timestamp": "2025-08-13T14:24:07.830591Z", "level": "ERROR", "logger": "main", "message": "Custom exception occurred: Username or email does not exist.", "module": "main", "function": "custom_exception_handler", "line": 150, "endpoint": "/user/login", "method": "POST", "status_code": 404}
{"timestamp": "2025-08-13T15:17:29.402528Z", "level": "ERROR", "logger": "main", "message": "Custom exception occurred: Could not validate credentials: Signature has expired.", "module": "main", "function": "custom_exception_handler", "line": 150, "endpoint": "/user/me", "method": "GET", "status_code": 401}
{"timestamp": "2025-08-13T15:17:38.378954Z", "level": "ERROR", "logger": "main", "message": "Custom exception occurred: Could not validate credentials: Signature has expired.", "module": "main", "function": "custom_exception_handler", "line": 150, "endpoint": "/user/me", "method": "GET", "status_code": 401}
{"timestamp": "2025-08-13T19:13:43.676835Z", "level": "ERROR", "logger": "main", "message": "Custom exception occurred: Could not validate credentials: Signature has expired.", "module": "main", "function": "custom_exception_handler", "line": 150, "endpoint": "/user/me", "method": "GET", "status_code": 401}
{"timestamp": "2025-08-15T15:18:06.599603Z", "level": "ERROR", "logger": "main", "message": "Custom exception occurred: Could not validate credentials: Signature has expired.", "module": "main", "function": "custom_exception_handler", "line": 133, "endpoint": "/user/me", "method": "GET", "status_code": 401}
{"timestamp": "2025-08-16T19:36:54.065090Z", "level": "ERROR", "logger": "main", "message": "Custom exception occurred: Could not validate credentials: Signature has expired.", "module": "main", "function": "custom_exception_handler", "line": 133, "endpoint": "/user/me", "method": "GET", "status_code": 401}
{"timestamp": "2025-08-16T20:19:20.879362Z", "level": "ERROR", "logger": "main", "message": "Custom exception occurred: Could not validate credentials: Signature has expired.", "module": "main", "function": "custom_exception_handler", "line": 133, "endpoint": "/user/me", "method": "GET", "status_code": 401}
{"timestamp": "2025-08-16T20:33:04.114813Z", "level": "ERROR", "logger": "main", "message": "Custom exception occurred: Could not validate credentials: Signature has expired.", "module": "main", "function": "custom_exception_handler", "line": 135, "endpoint": "/user/me", "method": "GET", "status_code": 401}
{"timestamp": "2025-08-16T21:25:42.827635Z", "level": "ERROR", "logger": "main", "message": "Custom exception occurred: Could not validate credentials: Signature has expired.", "module": "main", "function": "custom_exception_handler", "line": 133, "endpoint": "/user/me", "method": "GET", "status_code": 401}
{"timestamp": "2025-08-16T21:27:43.796589Z", "level": "ERROR", "logger": "main", "message": "Custom exception occurred: Could not validate credentials: Signature has expired.", "module": "main", "function": "custom_exception_handler", "line": 133, "endpoint": "/user/me", "method": "GET", "status_code": 401}
{"timestamp": "2025-08-17T10:30:45.011554Z", "level": "ERROR", "logger": "main", "message": "Custom exception occurred: Could not validate credentials: Signature has expired.", "module": "main", "function": "custom_exception_handler", "line": 133, "endpoint": "/user/me", "method": "GET", "status_code": 401}
{"timestamp": "2025-08-17T11:56:05.468146Z", "level": "ERROR", "logger": "main", "message": "Custom exception occurred: Could not validate credentials: Signature has expired.", "module": "main", "function": "custom_exception_handler", "line": 133, "endpoint": "/admin/products", "method": "GET", "status_code": 401}
{"timestamp": "2025-08-17T11:56:08.029219Z", "level": "ERROR", "logger": "main", "message": "Custom exception occurred: Could not validate credentials: Signature has expired.", "module": "main", "function": "custom_exception_handler", "line": 133, "endpoint": "/user/me", "method": "GET", "status_code": 401}
{"timestamp": "2025-09-01T07:54:47.841782Z", "level": "ERROR", "logger": "error_tracker", "message": "Exception occurred: ServerSelectionTimeoutError: No replica set members found yet, Timeout: 5.0s, Topology Description: <TopologyDescription id: 68b55142ec242f09907189ca, topology_type: ReplicaSetNoPrimary, servers: [<ServerDescription ('mongodb1-0622d3f8.mongo.ondigitalocean.com', 27017) server_type: Unknown, rtt: None>]>", "module": "logging_config", "function": "capture_exception", "line": 196, "exception": {"type": "ServerSelectionTimeoutError", "message": "No replica set members found yet, Timeout: 5.0s, Topology Description: <TopologyDescription id: 68b55142ec242f09907189ca, topology_type: ReplicaSetNoPrimary, servers: [<ServerDescription ('mongodb1-0622d3f8.mongo.ondigitalocean.com', 27017) server_type: Unknown, rtt: None>]>", "traceback": "Traceback (most recent call last):\n  File \"D:\\Some Random Needful Shit\\OneDrive\\Documents\\GitHub\\MonkeyZ\\backend\\src\\lib\\database_manager.py\", line 163, in connect\n    await self.client.admin.command('ping')\n  File \"C:\\Users\\user\\AppData\\Local\\Programs\\Python\\Python313\\Lib\\concurrent\\futures\\thread.py\", line 59, in run\n    result = self.fn(*self.args, **self.kwargs)\n  File \"C:\\Users\\user\\AppData\\Local\\Programs\\Python\\Python313\\Lib\\site-packages\\pymongo\\_csot.py\", line 120, in csot_wrapper\n    return func(self, *args, **kwargs)\n  File \"C:\\Users\\user\\AppData\\Local\\Programs\\Python\\Python313\\Lib\\site-packages\\pymongo\\synchronous\\database.py\", line 906, in command\n    with self._client._conn_for_reads(read_preference, session, operation=command_name) as (\n         ~~~~~~~~~~~~~~~~~~~~~~~~~~~~^^^^^^^^^^^^^^^^^^^^^^^^^^^^^^^^^^^^^^^^^^^^^^^^^^\n  File \"C:\\Users\\user\\AppData\\Local\\Programs\\Python\\Python313\\Lib\\site-packages\\pymongo\\synchronous\\mongo_client.py\", line 1701, in _conn_for_reads\n    server = self._select_server(read_preference, session, operation)\n  File \"C:\\Users\\user\\AppData\\Local\\Programs\\Python\\Python313\\Lib\\site-packages\\pymongo\\synchronous\\mongo_client.py\", line 1649, in _select_server\n    server = topology.select_server(\n        server_selector,\n    ...<2 lines>...\n        operation_id=operation_id,\n    )\n  File \"C:\\Users\\user\\AppData\\Local\\Programs\\Python\\Python313\\Lib\\site-packages\\pymongo\\synchronous\\topology.py\", line 397, in select_server\n    server = self._select_server(\n        selector,\n    ...<4 lines>...\n        operation_id=operation_id,\n    )\n  File \"C:\\Users\\user\\AppData\\Local\\Programs\\Python\\Python313\\Lib\\site-packages\\pymongo\\synchronous\\topology.py\", line 375, in _select_server\n    servers = self.select_servers(\n        selector, operation, server_selection_timeout, address, operation_id\n    )\n  File \"C:\\Users\\user\\AppData\\Local\\Programs\\Python\\Python313\\Lib\\site-packages\\pymongo\\synchronous\\topology.py\", line 282, in select_servers\n    server_descriptions = self._select_servers_loop(\n        selector, server_timeout, operation, operation_id, address\n    )\n  File \"C:\\Users\\user\\AppData\\Local\\Programs\\Python\\Python313\\Lib\\site-packages\\pymongo\\synchronous\\topology.py\", line 332, in _select_servers_loop\n    raise ServerSelectionTimeoutError(\n        f\"{self._error_message(selector)}, Timeout: {timeout}s, Topology Description: {self.description!r}\"\n    )\npymongo.errors.ServerSelectionTimeoutError: No replica set members found yet, Timeout: 5.0s, Topology Description: <TopologyDescription id: 68b55142ec242f09907189ca, topology_type: ReplicaSetNoPrimary, servers: [<ServerDescription ('mongodb1-0622d3f8.mongo.ondigitalocean.com', 27017) server_type: Unknown, rtt: None>]>"}}
{"timestamp": "2025-09-01T07:54:47.913870Z", "level": "ERROR", "logger": "src.lib.database_manager", "message": "Database initialization failed", "module": "database_manager", "function": "initialize_database", "line": 342}
{"timestamp": "2025-09-01T07:54:47.914201Z", "level": "ERROR", "logger": "main", "message": "Failed to initialize database connection", "module": "main", "function": "startup_event", "line": 216}
